Workbook
Name MyCell: Data!$B$2
Name MyName: Data!$A$1:$A$5

Sheet Data
A1: 1 | B1: 10 | D1: alpha
A2: 2 | B2: 20 | D2: beta
A3: 3 | B3: 30
A4: 4 | B4: 40
A5: 5 | B5: 50
A6: 6 | B6: 60
A7: 7 | B7: 70
A8: 8 | B8: 80
A9: 9 | B9: 90
A10: 10 | B10: 100
A11: 11 | B11: 110
A12: 12 | B12: 120
A13: 13 | B13: 130
A14: 14 | B14: 140
... A20: 20 | B20: 200

Sheet Sheet Space
A1: 100
A2: 200
A3: 300
A4: 400
A5: 500
A6: 600
A7: 700
A8: 800
A9: 900
A10: 1000

Sheet Formulas
A1: 1 | B1: 3 | D1: =A1+A2 -> 3 | E1: A1+A2
A2: 2 | B2: 6 | D2: =A1-A2 -> -1 | E2: A1-A2
A3: 3 | B3: 9 | D3: =A1*A2 -> 2 | E3: A1*A2
A4: 4 | B4: 12 | D4: =A1/A2 -> 0.5 | E4: A1/A2
A5: 5 | B5: 15 | D5: =A1^A2 -> 1 | E5: A1^A2
A6: 6 | B6: 18 | D6: =A1&A2 -> 12 | E6: A1&A2
A7: 7 | B7: 21 | D7: =A1<A2 -> TRUE | E7: A1<A2
A8: 8 | B8: 24 | D8: =A1<=A2 -> TRUE | E8: A1<=A2
A9: 9 | B9: 27 | D9: =A1=A2 -> FALSE | E9: A1=A2
A10: 10 | B10: 30 | D10: =A1>=A2 -> FALSE | E10: A1>=A2
A11: 11 | B11: 33 | D11: =A1>A2 -> FALSE | E11: A1>A2
A12: 12 | B12: 36 | D12: =A1<>A2 -> TRUE | E12: A1<>A2
A13: 13 | B13: 39 | D13: =-A1 -> -1 | E13: -A1
A14: 14 | B14: 42 | D14: =+A1 -> 1 | E14: +A1
A15: 15 | B15: 45 | D15: =A1% -> 0.01 | E15: A1%
A16: 16 | B16: 48 | D16: =(A1+A2)*A3 -> 9 | E16: (A1+A2)*A3
A17: 17 | B17: 51 | D17: =A1+A2*A3 -> 7 | E17: A1+A2*A3
A18: 18 | B18: 54 | D18: =(A1+A2)/(A3-A4) -> -3 | E18: (A1+A2)/(A3-A4)
A19: 19 | B19: 57 | D19: =1 -> 1 | E19: 1
A20: 20 | B20: 60 | D20: =1.5 -> 1.5 | E20: 1.5
D21: =-1.5 -> -1.5 | E21: -1.5
D22: =1000000 -> 1000000 | E22: 1000000
D23: ="hello" -> hello | E23: "hello"
D24: ="quote""inside" -> quote"inside | E24: "quote""inside"
D25: =TRUE -> TRUE | E25: TRUE
D26: =FALSE -> FALSE | E26: FALSE
D27: =#REF! -> #REF! | E27: #REF!
D28: =#DIV/0! -> #DIV/0! | E28: #DIV/0!
D29: =#N/A -> #N/A | E29: #N/A
D30: =A1 -> 1 | E30: A1
D31: =$A$1 -> 1 | E31: $A$1
D32: =$A1 -> 1 | E32: $A1
D33: =A$1 -> 1 | E33: A$1
D34: =A1:A5 -> #VALUE! | E34: A1:A5
D35: =$A$1:$A$5 -> #VALUE! | E35: $A$1:$A$5
D36: =A$1:$A5 -> #VALUE! | E36: A$1:$A5
D37: =SUM(A1:A5) -> 15 | E37: SUM(A1:A5)
D38: =SUM($A$1:$A$5) -> 15 | E38: SUM($A$1:$A$5)
D39: =SUM(A:A) -> 210 | E39: SUM(A:A)
D40: =SUM(1:1) -> 7 | E40: SUM(1:1)
...
